<?xml version="1.0"?>
<robot name="hawaii" xmlns:xacro="http://ros.org/wiki/xacro">

  <xacro:property name="robot_model"
    value="hawaii"
    scope="global"/>
  <xacro:property name="dof"
    value="5"
    scope="global"/>

  <xacro:arg name="robot_name"                      default="${robot_model}"/>
  <xacro:arg name="base_link_frame"                 default="base_link"/>
  <xacro:arg name="use_gripper"                     default="true"/>
  <xacro:arg name="show_ar_tag"                     default="false"/>
  <xacro:arg name="show_gripper_bar"                default="true"/>
  <xacro:arg name="show_gripper_fingers"            default="true"/>
  <xacro:arg name="use_world_frame"                 default="true"/>
  <xacro:arg name="external_urdf_loc"               default=""/>
  <xacro:arg name="hardware_type"                   default="actual"/>

  <xacro:property name="mesh_directory"             value="package://hawaii_descriptions/meshes/${robot_model}_meshes/"/>
  <xacro:property name="urdf_loc"                   value="$(arg external_urdf_loc)"/>
  <xacro:property name="hardware_type"              value="$(arg hardware_type)"/>
  <xacro:property name="pi_offset"                  value="0.00001"/>

  <xacro:property name="waist_limit_effort"         value="10"/>
  <xacro:property name="waist_limit_lower"          value="${-pi + pi_offset}"/>
  <xacro:property name="waist_limit_upper"          value="${pi - pi_offset}"/>
  <xacro:property name="waist_limit_vel"            value="${pi}"/>

  <xacro:property name="shoulder_limit_effort"      value="20"/>
  <xacro:property name="shoulder_limit_lower"       value="${radians(-106)}"/>
  <xacro:property name="shoulder_limit_upper"       value="${radians(72)}"/>
  <xacro:property name="shoulder_limit_vel"         value="${pi}"/>

  <xacro:property name="elbow_limit_effort"         value="15"/>
  <xacro:property name="elbow_limit_lower"          value="${radians(-101)}"/>
  <xacro:property name="elbow_limit_upper"          value="${radians(92)}"/>
  <xacro:property name="elbow_limit_vel"            value="${pi}"/>

  <xacro:property name="wrist_angle_limit_effort"   value="5"/>
  <xacro:property name="wrist_angle_limit_lower"    value="${radians(-107)}"/>
  <xacro:property name="wrist_angle_limit_upper"    value="${radians(128)}"/>
  <xacro:property name="wrist_angle_limit_vel"      value="${pi}"/>

  <xacro:property name="wrist_rotate_limit_effort"  value="1"/>
  <xacro:property name="wrist_rotate_limit_lower"   value="${-pi + pi_offset}"/>
  <xacro:property name="wrist_rotate_limit_upper"   value="${pi - pi_offset}"/>
  <xacro:property name="wrist_rotate_limit_vel"     value="${pi}"/>

  <xacro:property name="gripper_limit_vel"          value="${pi}"/>

  <xacro:property name="finger_limit_effort"        value="5"/>
  <xacro:property name="finger_limit_lower"         value="0.021"/>
  <xacro:property name="finger_limit_upper"         value="0.057"/>
  <xacro:property name="finger_limit_vel"           value="1"/>

  <material name="interbotix_black">
    <texture filename="package://hawaii_descriptions/meshes/interbotix_black.png"/>
  </material>

  <xacro:if value="$(arg use_world_frame)">
    <link name="world"/>
    <joint name="fixed" type="fixed">
      <parent
        link="world"/>
      <child
        link="$(arg robot_name)/$(arg base_link_frame)"/>
    </joint>
  </xacro:if> <!-- use_world_frame -->

  <link name="$(arg robot_name)/$(arg base_link_frame)">
    <visual>
      <origin
        rpy="0 0 ${pi/2}"
        xyz="0 0 0"/>
      <geometry>
        <mesh
          filename="${mesh_directory}/base.stl"
          scale="0.001 0.001 0.001"/>
      </geometry>
      <material name="interbotix_black"/>
    </visual>
    <collision>
      <origin
        rpy="0 0 ${pi/2}"
        xyz="0 0 0"/>
      <geometry>
        <mesh
          filename="${mesh_directory}/base.stl"
          scale="0.001 0.001 0.001"/>
      </geometry>
    </collision>
    <inertial>
      <origin
        rpy="0 0 ${pi/2}"
        xyz="-0.0534774000 -0.0005625750 0.0205961000"/>
      <mass value="0.969034"/>
      <inertia
        ixx="0.0060240000"
        iyy="0.0017000000"
        izz="0.0071620000"
        ixy="0.0000471300"
        ixz="0.0000038510"
        iyz="-0.0000841500"/>
    </inertial>
  </link>

  <joint name="waist" type="revolute">
    <axis xyz="0 0 1"/>
    <limit
      effort="${waist_limit_effort}"
      lower="${waist_limit_lower}"
      upper="${waist_limit_upper}"
      velocity="${waist_limit_vel}"/>
    <origin
      rpy="0 0 0"
      xyz="0 0 0.079"/>
    <parent
      link="$(arg robot_name)/$(arg base_link_frame)"/>
    <child
      link="$(arg robot_name)/shoulder_link"/>
    <dynamics
      friction="0.1"
      damping="0.1"/>
  </joint>

  <link name="$(arg robot_name)/shoulder_link">
    <visual>
      <origin
        rpy="0 0 ${pi/2}"
        xyz="0 0 -0.003"/>
      <geometry>
        <mesh
          filename="${mesh_directory}/shoulder.stl"
          scale="0.001 0.001 0.001"/>
      </geometry>
      <material name="interbotix_black"/>
    </visual>
    <collision>
      <origin
        rpy="0 0 ${pi/2}"
        xyz="0 0 -0.003"/>
      <geometry>
        <mesh
          filename="${mesh_directory}/shoulder.stl"
          scale="0.001 0.001 0.001"/>
      </geometry>
    </collision>
    <inertial>
      <origin
        rpy="0 0 ${pi/2}"
        xyz="0.0002592330 -0.0000033552 0.0116129000"/>
      <mass value="0.798614"/>
      <inertia
        ixx="0.0009388000"
        iyy="0.0011380000"
        izz="0.0012010000"
        ixy="-0.0000000010"
        ixz="-0.0000000191"
        iyz="0.0000059568"/>
    </inertial>
  </link>

  <xacro:include filename="$(find hawaii_descriptions)/urdf/control.urdf.xacro"/>

  <xacro:if value="${urdf_loc != ''}">
    <xacro:include filename="${urdf_loc}"/>
  </xacro:if>

</robot>
