<?xml version="1.0"?>
<robot name="Student_Arm" xmlns:xacro="http://ros.org/wiki/xacro"> 
  
  <xacro:property name="robot_name"                 default="Student_Arm"/>
  <xacro:property name="J1_limit_effort"            value="0"/>
  <xacro:property name="J1_limit_lower"             value="${-pi}"/>
  <xacro:property name="J1_limit_upper"             value="${pi}"/>
  <xacro:property name="J1_limit_vel"               value="${pi}"/>

  <xacro:property name="J2_limit_effort"            value="0"/>
  <xacro:property name="J2_limit_lower"             value="-1.5708"/>
  <xacro:property name="J2_limit_upper"             value="1.5708"/>
  <xacro:property name="J2_limit_vel"               value="${pi}"/>

  <xacro:property name="J3_limit_effort"            value="0"/>
  <xacro:property name="J3_limit_lower"             value="0"/>
  <xacro:property name="J3_limit_upper"             value="${pi}"/>
  <xacro:property name="J3_limit_vel"               value="${pi}"/>

  <xacro:property name="J4_limit_effort"            value="0"/>
  <xacro:property name="J4_limit_lower"             value="${-pi}"/>
  <xacro:property name="J4_limit_upper"             value="${pi}"/>
  <xacro:property name="J4_limit_vel"               value="${pi}"/>

  <xacro:property name="J5_limit_effort"            value="0"/>
  <xacro:property name="J5_limit_lower"             value="0"/>
  <xacro:property name="J5_limit_upper"             value="${pi}"/>
  <xacro:property name="J5_limit_vel"               value="${pi}"/>

  <xacro:property name="J6_limit_effort"            value="0"/>
  <xacro:property name="J6_limit_lower"             value="${-pi}"/>
  <xacro:property name="J6_limit_upper"             value="${pi}"/>
  <xacro:property name="J6_limit_vel"               value="${pi}"/>

  <xacro:property name="GR_limit_effort"            value="5"/>
  <xacro:property name="GR_limit_lower"             value="0"/>
  <xacro:property name="GR_limit_upper"             value="0.057"/>
  <xacro:property name="GR_limit_vel"               value="1"/>

  <xacro:property name="GL_limit_effort"            value="5"/>
  <xacro:property name="GL_limit_lower"             value="0"/>
  <xacro:property name="GL_limit_upper"             value="0.057"/>
  <xacro:property name="GL_limit_vel"               value="1"/>

  <link name="world"/>
  <joint name="fixed" type="fixed">
    <parent link="world"/>
    <child link="$(arg robot_name)/base_link"/>
  </joint>
  <link name="$(arg robot_name)/base_link">
    <inertial>
      <origin
        xyz="3.75969511884504E-08 0.0026277370286045 -0.0794517403190993"
        rpy="0 0 0" />
      <mass
        value="0.53383345184999" />
      <inertia
        ixx="0.00120475867367635"
        ixy="-2.59729358055544E-09"
        ixz="1.27494390418459E-09"
        iyy="0.00118360373666522"
        iyz="-4.04496125401089E-08"
        izz="0.00226030030514847" />
    </inertial>
    <visual>
      <origin
        xyz="0 0 0"
        rpy="0 0 0" />
      <geometry>
        <mesh
          filename="package://hawaii_descriptions/meshes/hawaii_meshes/base_link.STL" />
      </geometry>
      <material
        name="">
        <color
          rgba="0.898039215686275 0.898039215686275 0.898039215686275 1" />
      </material>
    </visual>
    <collision>
      <origin
        xyz="0 0 0"
        rpy="0 0 0" />
      <geometry>
        <mesh
          filename="package://hawaii_descriptions/meshes/hawaii_meshes/base_link.STL" />
      </geometry>
    </collision>
  </link>
  <link name="$(arg robot_name)/J1">
    <inertial>
      <origin
        xyz="8.00258875598234E-17 -0.043916645765684 -0.000151589790021581"
        rpy="0 0 0" />
      <mass
        value="0.503990921516619" />
      <inertia
        ixx="0.000419374261334047"
        ixy="-1.02360622953232E-18"
        ixz="-6.38048690662538E-13"
        iyy="0.000727556052551127"
        iyz="1.14884368640365E-07"
        izz="0.000433260463010681" />
    </inertial>
    <visual>
      <origin
        xyz="0 0 0"
        rpy="0 0 0" />
      <geometry>
        <mesh
          filename="package://hawaii_descriptions/meshes/hawaii_meshes/J1.STL" />
      </geometry>
      <material
        name="">
        <color
          rgba="0.898039215686275 0.917647058823529 0.929411764705882 1" />
      </material>
    </visual>
    <collision>
      <origin
        xyz="0 0 0"
        rpy="0 0 0" />
      <geometry>
        <mesh
          filename="package://hawaii_descriptions/meshes/hawaii_meshes/J1.STL" />
      </geometry>
    </collision>
  </link>
  <joint name="Joint1"
    type="revolute">
    <origin
      xyz="0 0 0"
      rpy="1.5708 0 0" />
    <parent
      link="$(arg robot_name)/base_link" />
    <child
      link="$(arg robot_name)/J1" />
    <axis
      xyz="0 1 0" />
    <limit
      effort="${J1_limit_effort}"
      lower="${J1_limit_lower}"
      upper="${J1_limit_upper}"
      velocity="${J1_limit_vel}"/>
  </joint>
  <link name="$(arg robot_name)/J2">
    <inertial>
      <origin
        xyz="-0.0106610998558658 0.0996577699603199 -0.0225833036054658"
        rpy="0 0 0" />
      <mass
        value="0.392789177538168" />
      <inertia
        ixx="0.000396426299261622"
        ixy="3.05426079350919E-06"
        ixz="5.19393396036676E-08"
        iyy="0.000310968257095633"
        iyz="-5.32515111591185E-09"
        izz="0.000173145285634184" />
    </inertial>
    <visual>
      <origin
        xyz="0 0 0"
        rpy="0 0 0" />
      <geometry>
        <mesh
          filename="package://hawaii_descriptions/meshes/hawaii_meshes/J2.STL" />
      </geometry>
      <material
        name="">
        <color
          rgba="1 0.949019607843137 0.874509803921569 1" />
      </material>
    </visual>
    <collision>
      <origin
        xyz="0 0 0"
        rpy="0 0 0" />
      <geometry>
        <mesh
          filename="package://hawaii_descriptions/meshes/hawaii_meshes/J2.STL" />
      </geometry>
    </collision>
  </link>
  <joint
    name="Joint2"
    type="revolute">
    <origin
      xyz="0.0221 0 0"
      rpy="1.5708 1.5708 1.5708" />
    <parent
      link="$(arg robot_name)/J1" />
    <child
      link="$(arg robot_name)/J2" />
    <axis
      xyz="0 0 -1" />
    <limit
      effort="${J2_limit_effort}"
      lower="${J2_limit_lower}"
      upper="${J2_limit_upper}"
      velocity="${J2_limit_vel}"/>
  </joint>
  <link
    name="$(arg robot_name)/J3">
    <inertial>
      <origin
        xyz="-5.4174E-06 -0.095818 0.018544"
        rpy="0 0 0" />
      <mass
        value="0.20982" />
      <inertia
        ixx="0.00010657"
        ixy="4.3117E-08"
        ixz="8.2991E-10"
        iyy="7.5396E-05"
        iyz="-1.2745E-06"
        izz="7.1513E-05" />
    </inertial>
    <visual>
      <origin
        xyz="0 0 0"
        rpy="0 0 0" />
      <geometry>
        <mesh
          filename="package://hawaii_descriptions/meshes/hawaii_meshes/J3.STL" />
      </geometry>
      <material
        name="">
        <color
          rgba="1 0.94902 0.87451 1" />
      </material>
    </visual>
    <collision>
      <origin
        xyz="0 0 0"
        rpy="0 0 0" />
      <geometry>
        <mesh
          filename="package://hawaii_descriptions/meshes/hawaii_meshes/J3.STL" />
      </geometry>
    </collision>
  </link>
  <joint
    name="Joint3"
    type="revolute">
    <origin
      xyz="-0.06275 0.242 0"
      rpy="-3.1416 0 3.1416" />
    <parent
      link="$(arg robot_name)/J2" />
    <child
      link="$(arg robot_name)/J3" />
    <axis
      xyz="0 0 1" />
    <limit
      effort="${J3_limit_effort}"
      lower="${J3_limit_lower}"
      upper="${J3_limit_upper}"
      velocity="${J3_limit_vel}"/>
  </joint>
  <link
    name="$(arg robot_name)/J4">
    <inertial>
      <origin
        xyz="0.000220187546183284 0.00131330393669656 -0.00131330397228391"
        rpy="0 0 0" />
      <mass
        value="0.060711039584101" />
      <inertia
        ixx="1.24543917386626E-05"
        ixy="-2.80072544359706E-08"
        ixz="2.80072615395398E-08"
        iyy="1.06706749274675E-05"
        iyz="1.97798843517771E-06"
        izz="1.06706749477743E-05" />
    </inertial>
    <visual>
      <origin
        xyz="0 0 0"
        rpy="0 0 0" />
      <geometry>
        <mesh
          filename="package://hawaii_descriptions/meshes/hawaii_meshes/J4.STL" />
      </geometry>
      <material
        name="">
        <color
          rgba="0.776470588235294 0.756862745098039 0.737254901960784 1" />
      </material>
    </visual>
    <collision>
      <origin
        xyz="0 0 0"
        rpy="0 0 0" />
      <geometry>
        <mesh
          filename="package://hawaii_descriptions/meshes/hawaii_meshes/J4.STL" />
      </geometry>
    </collision>
  </link>
  <joint
    name="Joint4"
    type="revolute">
    <origin
      xyz="0 -0.232125103077643 0.0220999999999999"
      rpy="0.785398163397452 1.5707963267949 0" />
    <parent
      link="$(arg robot_name)/J3" />
    <child
      link="$(arg robot_name)/J4" />
    <axis
      xyz="0 0.707106781186543 -0.707106781186552" />
    <limit
      effort="${J4_limit_effort}"
      lower="${J4_limit_lower}"
      upper="${J4_limit_upper}"
      velocity="${J4_limit_vel}"/>
  </joint>
  <link
    name="$(arg robot_name)/J5">
    <inertial>
      <origin
        xyz="-0.019335080438349 0.0351625780910085 7.23341200059109E-05"
        rpy="0 0 0" />
      <mass
        value="0.0534742460950701" />
      <inertia
        ixx="1.00219216800762E-05"
        ixy="-1.68795010015771E-06"
        ixz="1.06688803293322E-14"
        iyy="9.08572755149546E-06"
        iyz="3.80777736800259E-15"
        izz="1.3557284681395E-05" />
    </inertial>
    <visual>
      <origin
        xyz="0 0 0"
        rpy="0 0 0" />
      <geometry>
        <mesh
          filename="package://hawaii_descriptions/meshes/hawaii_meshes/J5.STL" />
      </geometry>
      <material
        name="">
        <color
          rgba="1 0.949019607843137 0.874509803921569 1" />
      </material>
    </visual>
    <collision>
      <origin
        xyz="0 0 0"
        rpy="0 0 0" />
      <geometry>
        <mesh
          filename="package://hawaii_descriptions/meshes/hawaii_meshes/J5.STL" />
      </geometry>
    </collision>
  </link>
  <joint
    name="Joint5"
    type="revolute">
    <origin
      xyz="0 -0.012639 0.012639"
      rpy="1.5708 1.5708 1.5708" />
    <parent
      link="$(arg robot_name)/J4" />
    <child
      link="$(arg robot_name)/J5" />
    <axis
      xyz="0 0 1" />
    <limit
      effort="${J5_limit_effort}"
      lower="${J5_limit_lower}"
      upper="${J5_limit_upper}"
      velocity="${J5_limit_vel}"/>
  </joint>
  <link
    name="$(arg robot_name)/J6">
    <inertial>
      <origin
        xyz="-0.0064673240335944 -0.00293644104444194 0.047256336077668"
        rpy="0 0 0" />
      <mass
        value="0.10498725932869" />
      <inertia
        ixx="1.33725101539202E-05"
        ixy="-3.44362818758654E-06"
        ixz="2.32769709578376E-07"
        iyy="1.93402341638447E-05"
        iyz="2.04901766859891E-07"
        izz="2.19519821270149E-05" />
    </inertial>
    <visual>
      <origin
        xyz="0 0 0"
        rpy="0 0 0" />
      <geometry>
        <mesh
          filename="package://hawaii_descriptions/meshes/hawaii_meshes/J6.STL" />
      </geometry>
      <material
        name="">
        <color
          rgba="1 0.949019607843137 0.874509803921569 1" />
      </material>
    </visual>
    <collision>
      <origin
        xyz="0 0 0"
        rpy="0 0 0" />
      <geometry>
        <mesh
          filename="package://hawaii_descriptions/meshes/hawaii_meshes/J6.STL" />
      </geometry>
    </collision>
  </link>
  <joint
    name="Joint6"
    type="revolute">
    <origin
      xyz="-0.0410888768161758 0.0397298912546164 0"
      rpy="1.5707963267949 0.409116990824611 -2.33938085233866" />
    <parent
      link="$(arg robot_name)/J5" />
    <child
      link="$(arg robot_name)/J6" />
    <axis
      xyz="0 0 1" />
    <limit
      effort="${J6_limit_effort}"
      lower="${J6_limit_lower}"
      upper="${J6_limit_upper}"
      velocity="${J6_limit_vel}"/>
  </joint>
  <link
    name="$(arg robot_name)/Gripper_Left">
    <inertial>
      <origin
        xyz="-0.043578 0.0054586 0.50483"
        rpy="0 0 0" />
      <mass
        value="0.018972" />
      <inertia
        ixx="9.0967E-06"
        ixy="-1.0831E-06"
        ixz="4.8722E-06"
        iyy="2.0138E-05"
        iyz="1.4189E-06"
        izz="1.2843E-05" />
    </inertial>
    <visual>
      <origin
        xyz="0 0 0"
        rpy="0 0 0" />
      <geometry>
        <mesh
          filename="package://hawaii_descriptions/meshes/hawaii_meshes/Gripper_Left.STL" />
      </geometry>
      <material
        name="">
        <color
          rgba="0.10196 0.10196 0.10196 1" />
      </material>
    </visual>
    <collision>
      <origin
        xyz="0 0 0"
        rpy="0 0 0" />
      <geometry>
        <mesh
          filename="package://hawaii_descriptions/meshes/hawaii_meshes/Gripper_Left.STL" />
      </geometry>
    </collision>
  </link>
  <joint
    name="GL"
    type="prismatic">
    <origin
      xyz="-0.00106483764465011 0.00245590949658455 -0.410608968248641"
      rpy="0 0 1.97991331761951" />
    <parent
      link="$(arg robot_name)/finger_link" />
    <child
      link="$(arg robot_name)/Gripper_Left" />
    <axis
      xyz="1 0 0" />
    <limit
      effort="${GL_limit_effort}"
      lower="${GL_limit_lower}"
      upper="${GL_limit_upper}"
      velocity="${GL_limit_vel}"/>
  </joint>
  <link
    name="$(arg robot_name)/Gripper_Right">
    <inertial>
      <origin
        xyz="0.0035414 -0.019521 0.034672"
        rpy="0 0 0" />
      <mass
        value="0.018972" />
      <inertia
        ixx="2.0138E-05"
        ixy="1.4189E-06"
        ixz="1.0831E-06"
        iyy="1.2843E-05"
        iyz="-4.8722E-06"
        izz="9.0967E-06" />
    </inertial>
    <visual>
      <origin
        xyz="0 0 0"
        rpy="0 0 0" />
      <geometry>
        <mesh
          filename="package://hawaii_descriptions/meshes/hawaii_meshes/Gripper_Right.STL" />
      </geometry>
      <material
        name="">
        <color
          rgba="0.79216 0.81961 0.93333 1" />
      </material>
    </visual>
    <collision>
      <origin
        xyz="0 0 0"
        rpy="0 0 0" />
      <geometry>
        <mesh
          filename="package://hawaii_descriptions/meshes/hawaii_meshes/Gripper_Right.STL" />
      </geometry>
    </collision>
  </link>
  <joint
    name="GR"
    type="prismatic">
    <origin
      xyz="-0.0218057092576579 0.0729165031249449 0.0746999999999995"
      rpy="-1.5707963267949 0 -2.73247566276518" />
    <parent
      link="$(arg robot_name)/finger_link" />
    <child
      link="$(arg robot_name)/Gripper_Right" />
    <axis
      xyz="0 0 1" />
    <limit
      effort="${GR_limit_effort}"
      lower="${GR_limit_lower}"
      upper="${GR_limit_upper}"
      velocity="${GR_limit_vel}"/>
    <mimic
      joint="GL"
      multiplier="1"
      offset="0" />
  </joint>
  <joint
    name="gripper"
    type="fixed">
    <origin
      xyz="0 0 0"
      rpy="0 0 0" />
    <parent
      link="$(arg robot_name)/J6" />
    <child
      link="$(arg robot_name)/finger_link" />
    <axis
      xyz="1 0 0" />
  </joint>
  <link name="$(arg robot_name)/finger_link">
  <inertial>
    <mass value="0.001"/>
    <inertia
      ixx="0.0001"
      iyy="0.0001"
      izz="0.0001"
      ixy="0"
      ixz="0"
      iyz="0"/>
  </inertial>
  </link>
</robot>
